<?xml version="1.0" ?>
<sdf version="1.9">
  <model name="humanoid_face">
    <static>false</static>

    <!-- Head -->
    <link name="head">
      <pose>0 0 0.5 0 0 0</pose>
      <collision name="head_collision">
        <geometry>
          <sphere>
            <radius>0.2</radius>
          </sphere>
        </geometry>
        <surface>
          <contact>
            <ode/>
          </contact>
        </surface>
      </collision>
      <visual name="head_visual">
        <geometry>
          <sphere>
            <radius>0.2</radius>
          </sphere>
        </geometry>
        <material>
          <ambient>0.8 0.6 0.5 1</ambient>
          <diffuse>0.8 0.6 0.5 1</diffuse>
        </material>
      </visual>
    </link>

    <!-- Left Eye -->
    <link name="left_eye">
      <pose>0.1 0.08 0.6 0 0 0</pose>
      <collision name="left_eye_collision">
        <geometry>
          <sphere>
            <radius>0.03</radius>
          </sphere>
        </geometry>
      </collision>
      <visual name="left_eye_visual">
        <geometry>
          <sphere>
            <radius>0.03</radius>
          </sphere>
          <material>
            <ambient>0 0 0 1</ambient>
            <diffuse>0 0 0 1</diffuse>
          </material>
        </visual>
    </link>

    <!-- Right Eye -->
    <link name="right_eye">
      <pose>0.1 -0.08 0.6 0 0 0</pose>
      <collision name="right_eye_collision">
        <geometry>
          <sphere>
            <radius>0.03</radius>
          </sphere>
        </geometry>
      </collision>
      <visual name="right_eye_visual">
        <geometry>
          <sphere>
            <radius>0.03</radius>
          </sphere>
          <material>
            <ambient>0 0 0 1</ambient>
            <diffuse>0 0 0 1</diffuse>
          </material>
        </visual>
    </link>

    <!-- Jaw -->
    <link name="jaw">
      <pose>0 0 -0.05 0 0 0</pose>
      <collision name="jaw_collision">
        <geometry>
          <box>
            <size>0.15 0.05 0.05</size>
          </box>
        </geometry>
      </collision>
      <visual name="jaw_visual">
        <geometry>
          <box>
            <size>0.15 0.05 0.05</size>
          </box>
          <material>
            <ambient>0.8 0.5 0.5 1</ambient>
            <diffuse>0.8 0.5 0.5 1</diffuse>
          </material>
        </visual>
    </link>

    <!-- Joints -->
    <joint name="jaw_joint" type="revolute">
      <parent>head</parent>
      <child>jaw</child>
      <pose>0 0 0.45 0 0 0</pose>
      <axis>
        <xyz>0 1 0</xyz>
        <limit>
          <lower>-0.5</lower>
          <upper>0.5</upper>
        </limit>
        <dynamics>
          <damping>0.1</damping>
        </dynamics>
      </axis>
    </joint>

    <joint name="left_eye_joint" type="revolute">
      <parent>head</parent>
      <child>left_eye</child>
      <pose>0 0 0.6 0 0 0</pose>
      <axis>
        <xyz>0 0 1</xyz>
        <limit>
          <lower>-0.2</lower>
          <upper>0.2</upper>
        </limit>
        <dynamics>
          <damping>0.1</damping>
        </dynamics>
      </axis>
    </joint>

    <joint name="right_eye_joint" type="revolute">
      <parent>head</parent>
      <child>right_eye</child>
      <pose>0 0 0.6 0 0 0</pose>
      <axis>
        <xyz>0 0 1</xyz>
        <limit>
          <lower>-0.2</lower>
          <upper>0.2</upper>
        </limit>
        <dynamics>
          <damping>0.1</damping>
        </dynamics>
      </axis>
    </joint>
  </model>
</sdf>

